tests/complex/complex_41.in
40
o
36 B 100 BLK 1426 358
31 S 101 ALE 1427 48
24 B 102 BAH 1815 361
15 S 103 AJX 1849 140
8 S 104 ATCO^I 1481 497
27 S 105 BDJ 826 426
21 B 106 ABR^E 437 956
20 B 107 AMWL 1370 470
30 S 108 ALIT 1898 770
3 S 109 ANAC 1501 93
6 S 110 ALEX 1559 308
18 B 111 AAIC^B 532 519
24 B 112 AEL^A 1025 454
8 S 113 AQUA 964 256
7 S 114 BGS 620 74
23 S 115 AFT 1671 389
19 B 116 ATUS 1219 563
28 B 117 AMC 1929 407
0 B 118 BAM 1898 91
10 B 119 AMAM 162 755
4 B 120 AKO/A 1889 847
22 S 121 AMBC 149 739
14 S 122 ATKR 1446 835
11 S 123 BBW 991 345
20 S 124 BAC^O 1720 166
18 B 125 ALC 1966 935
3 B 126 AIRC 936 908
31 B 127 AGM^C 320 119
33 S 128 AVYA 122 122
31 B 129 ASR 833 291
29 S 130 AXTA 109 227
24 S 131 BEKE 1223 817
5 B 132 AGM^C 1477 318
13 S 133 BIPC 763 221
25 S 134 ACR^C 1589 500
35 S 135 BC 1363 796
31 S 136 ADX 414 873
14 S 137 BC^B 1098 466
3 B 138 ABR 1141 61
0 S 139 ABEV 1119 562
33 B 140 BKI 1628 395
36 S 141 ARNC 1769 1000
23 B 142 BEDU 1669 113
2 S 143 APD 297 53
3 S 144 ALLE 784 314
29 S 145 AWI 307 586
17 S 146 AMK 1553 746
4 S 147 AMPS 911 767
35 B 148 ARMK 282 12
14 B 149 BEST 1317 757
34 S 150 BBLN 1972 587
26 B 151 BAC^K 631 229
30 B 152 BFLY 664 321
16 B 153 AMC 1594 912
12 S 154 ASGI 762 158
21 S 155 AAIC^B 1830 595
7 B 156 AQNU 1117 131
34 B 157 BIP 387 472
18 B 158 BHR^D 136 954
19 S 159 ARIS 682 630
35 S 160 ACI 1234 420
37 B 161 BBN 1744 527
17 S 162 AME 708 294
12 B 163 ATH^A 1647 876
24 B 164 AIZ 549 576
17 S 165 ASAN 1096 859
2 S 166 BAC^L 1434 909
37 S 167 AXAC 232 933
38 S 168 AEL^A 370 760
33 B 169 ASGI 747 694
20 S 170 AJXA 358 924
29 S 171 ANF 415 183
23 S 172 BGY 1759 425
10 S 173 AMR 518 212
32 B 174 AHT^H 261 195
38 B 175 ATCO^D 348 248
17 B 176 ATI 126 53
13 B 177 BMI 187 310
5 S 178 APLE 594 258
32 B 179 BLK 689 553
17 S 180 ALLG 1631 740
20 S 181 ALLY 569 258
10 S 182 AESC 691 915
37 B 183 BANC 1702 412
11 B 184 ADM 711 928
18 S 185 ARCO 519 838
24 B 186 AMPS 650 776
31 B 187 ADT 826 751
3 B 188 AMPX 1703 387
5 S 189 ARLO 1848 685
15 B 190 AWF 688 722
1 B 191 BCAT 1061 785
36 B 192 BHLB 1631 154
22 S 193 ABEV 495 520
9 B 194 BBWI 366 644
37 S 195 BIPC 1547 102
1 B 196 AP 1216 892
25 B 197 ATGE 1154 50
9 B 198 APRN 1587 862
20 S 199 BKT 840 850
14 B 200 BCS 1627 956
24 B 201 AGR 306 549
11 B 202 BBDC 505 522
8 B 203 ASC 1948 803
13 B 204 AEM 1267 301
14 S 205 ALSN 1351 498
24 B 206 ARCO 569 30
39 S 207 ASB^E 144 347
11 S 208 AQUA 1897 57
15 B 209 BE 819 784
32 S 210 BFS^E 228 279
34 B 211 ATCO 493 847
19 B 212 BCO 610 627
4 S 213 BIT 936 917
19 S 214 AVYA 1205 845
30 S 215 AMRX 386 267
9 S 216 BALL 655 971
4 B 217 AN 1629 726
29 S 218 BE 683 953
39 B 219 ACP 311 929
6 B 220 AWR 1636 890
0 S 221 BB 243 858
1 S 222 ATI 1649 286
13 B 223 AC 485 446
18 S 224 BCE 1609 927
14 B 225 BCH 192 637
29 B 226 ALV 1937 187
23 S 227 AIV 388 817
27 S 228 APH 182 517
6 B 229 BBW 1133 253
37 B 230 AZRE 1124 468
3 B 231 BHR^D 1325 602
34 B 232 AN 1112 99
18 B 233 ANF 569 747
19 S 234 BAC^S 587 512
6 S 235 APD 956 485
23 S 236 AVNS 740 821
25 S 237 ASAN 1523 272
6 S 238 APAM 1472 523
19 B 239 BIG 1807 466
1 S 240 AJRD 1788 318
19 B 241 BIP^A 1341 122
0 S 242 AM 147 676
2 B 243 BFLY 1275 510
16 S 244 ATKR 1252 865
13 S 245 BFS^D 341 363
34 B 246 AWK 1716 397
7 B 247 BMI 919 181
35 S 248 BBDO 1050 369
30 B 249 BALY 970 965
11 B 250 AXS^E 1025 160
25 S 251 AMBC 1114 64
14 B 252 ACI 1500 541
10 S 253 BFK 1201 794
19 S 254 AJG 1421 490
26 B 255 AX 384 566
7 B 256 AVY 362 421
33 S 257 AG 1760 620
21 S 258 BB 1536 993
14 B 259 AHT^G 567 56
34 S 260 AIC 1133 778
16 B 261 AZO 511 696
34 S 262 AMR 1678 851
1 B 263 BBDO 429 434
24 S 264 BAK 1621 226
20 S 265 BFZ 857 147
2 S 266 BHV 425 299
35 B 267 AGD 368 227
28 S 268 ACA 504 185
17 S 269 BDJ 370 264
37 B 270 ARGD 339 27
25 B 271 ACP^A 424 736
11 B 272 BG 1685 364
16 B 273 BGR 1193 362
27 S 274 BBVA 469 764
28 S 275 BACA 224 348
23 B 276 ASPN 1931 188
19 S 277 AORT 1598 755
25 S 278 BBDO 1215 960
21 S 279 BKD 140 197
26 B 280 BAM 1762 453
31 S 281 BMI 1580 760
35 B 282 AAN 1579 127
0 S 283 AIR 1379 669
11 S 284 BAP 453 66
7 B 285 AEL^B 1634 78
28 B 286 BBWI 513 439
3 B 287 ACR^D 1155 846
39 S 288 ACM 308 946
4 S 289 BIGZ 1604 828
0 S 290 ASPN 1314 201
9 B 291 AXR 1344 150
13 S 292 AHT^D 1261 958
27 S 293 BGX 243 126
21 B 294 ATI 678 612
5 B 295 ALTG^A 1193 710
39 S 296 AQUA 552 472
31 S 297 AL 1403 866
39 B 298 AIG 468 537
4 B 299 ASGN 381 670
31 S 300 ARES 1734 231
32 S 301 BIG 387 877
37 B 302 BFS^E 887 691
17 S 303 AHH 1562 316
18 B 304 AME 291 411
23 B 305 BHK 1181 390
4 S 306 BLND 1900 317
39 S 307 AC 950 606
36 B 308 AMX 1686 321
15 S 309 AI 679 780
27 B 310 BHG 295 195
30 S 311 ABM 1292 366
17 S 312 ASB 895 57
15 S 313 AXAC 1610 547
1 B 314 ATR 1202 408
18 B 315 ADC 278 412
29 B 316 AHH 1634 877
7 S 317 AHT 1926 454
6 S 318 AORT 958 405
23 S 319 ARE 934 52
24 S 320 BAP 111 193
21 B 321 BAC^E 709 379
7 S 322 BIG 183 791
2 B 323 AOMR 1272 38
30 B 324 AHT^H 1534 603
2 B 325 AFGB 1629 840
36 B 326 AKR 1763 156
35 S 327 ABR^F 1191 570
10 S 328 BBD 1936 144
28 S 329 ARGD 1227 294
36 S 330 BGSX 448 731
28 S 331 ALLE 244 186
12 S 332 ARI 1818 924
28 S 333 BAC^B 1250 645
1 S 334 ATI 1439 455
14 B 335 ABR^E 965 237
21 B 336 BIGZ 1322 804
8 B 337 AIV 734 571
17 S 338 AXR 686 107
21 B 339 AMN 615 725
29 B 340 ARI 422 372
7 B 341 ACA 1829 772
37 B 342 ACR^C 1935 750
27 S 343 BIP^B 1393 317
33 B 344 ADX 962 966
32 S 345 AGM 870 918
22 S 346 ATH^A 522 833
21 B 347 AIZ 940 465
12 S 348 AXP 910 860
23 B 349 BF/A 726 424
32 B 350 AZZ 666 661
4 B 351 BIPH 666 139
19 B 352 AGAC 363 691
8 B 353 BHLB 1969 585
19 B 354 AEO 1736 688
13 S 355 BA 1792 662
10 B 356 ATTO 1621 51
1 B 357 ASB 559 902
4 B 358 ARW 273 617
30 B 359 ARLO 1289 310
7 B 360 ARL 926 649
23 B 361 ACI 461 843
25 B 362 BCSF 874 32
17 B 363 ASH 1557 110
27 B 364 ASH 638 197
39 B 365 ATTO 1344 666
35 B 366 AHT 741 933
30 B 367 BAK 660 724
31 S 368 AN 1628 399
15 B 369 BF/B 717 346
31 S 370 AYX 374 361
25 S 371 APAM 1346 714
37 B 372 BHV 139 824
10 S 373 BGSF 1128 534
36 S 374 ADCT 752 48
34 S 375 AMWL 1912 470
35 S 376 AAIC 1183 470
17 S 377 AROC 1830 638
11 B 378 AGM 1454 602
30 B 379 BHR 1399 867
11 B 380 AG 431 687
29 S 381 AXS^E 807 20
5 B 382 BFS 829 945
22 S 383 BLW 1368 566
14 B 384 ANET 1773 134
27 B 385 AVAL 670 837
33 B 386 AMOV 1716 667
4 S 387 BC^C 1319 495
21 S 388 BAC^M 1716 225
7 S 389 AMP 1474 859
6 S 390 BEDU 629 682
35 B 391 AORT 242 870
16 S 392 BML^G 1617 852
8 B 393 AVA 1836 804
0 S 394 AVTR 1350 373
38 S 395 BGR 1052 161
7 B 396 APCA 453 302
28 S 397 ADX 1866 315
1 S 398 AM 1546 834
0 S 399 BAC^K 1444 792
8 S 400 AQNU 1052 619
7 B 401 BFLY 1437 210
14 B 402 BKDT 1116 14
4 S 403 BCX 1630 346
15 B 404 AM 142 134
0 S 405 AAIC^B 589 714
4 B 406 BFAM 1915 474
13 S 407 ABG 1583 620
21 S 408 ATUS 157 619
11 B 409 ACA 342 677
22 S 410 BABA 1415 250
25 S 411 BA 1875 78
26 S 412 ACRE 574 279
6 S 413 A 567 71
13 B 414 BLD 392 466
31 S 415 BEP^A 1430 810
21 S 416 AFGB 1642 407
4 S 417 ARIS 542 809
13 B 418 BA 732 757
30 S 419 BMEZ 515 587
24 S 420 ATCO^D 1111 899
0 S 421 BKH 1998 723
1 B 422 APLE 670 702
12 S 423 AMG 1794 260
37 S 424 APH 1186 986
34 B 425 AEG 932 411
16 S 426 ASB^E 505 817
38 S 427 AL^A 452 382
21 S 428 APG 214 518
3 S 429 AEG 532 38
23 B 430 AMC 1709 90
3 S 431 ALEX 345 230
11 B 432 ABBV 473 922
13 S 433 BCO 509 108
19 S 434 AGM 127 296
5 B 435 BJ 1959 144
31 B 436 AHL^C 878 281
14 S 437 AMAM 1926 960
30 B 438 AMOV 715 827
34 S 439 AVAL 1316 824
12 S 440 BIO 1114 819
15 S 441 ALTG 292 299
35 B 442 BEST 1129 496
4 B 443 BBN 1062 391
16 B 444 BFAM 1000 649
8 B 445 ATH^B 1100 990
27 S 446 AIR 1819 680
13 S 447 BEDU 337 600
39 B 448 BIPI 178 703
21 S 449 AHT^D 857 251
6 B 450 ABR^D 546 119
13 B 451 BJ 222 16
25 B 452 BC^C 1120 720
13 B 453 AGM^E 551 559
3 S 454 AP 1923 434
10 S 455 AIU 1885 260
37 S 456 ANF 694 596
24 S 457 AIO 1135 205
3 B 458 BC^C 517 224
25 B 459 ARGO 658 451
15 S 460 BKKT 1976 165
14 B 461 ADNT 759 660
1 S 462 BAC^M 742 506
33 B 463 BALY 1348 291
25 B 464 BIG 1887 770
12 B 465 ALC 1425 665
24 S 466 ATUS 1287 181
