tests/complex/complex_44.in
40
o
12 B 100 AHL^C 883 766
3 B 101 BBUC 914 662
33 S 102 BJ 1016 392
23 S 103 BAC^L 775 464
15 S 104 ATKR 1139 83
1 S 105 ATCO^I 778 189
0 S 106 BJ 223 468
18 S 107 BC^A 918 585
9 B 108 AAM^A 1919 826
9 S 109 ASG 532 784
29 B 110 ARMK 1504 390
10 B 111 ALTG^A 1912 380
31 B 112 ATR 670 366
1 S 113 AGR 1205 17
27 B 114 AVY 1806 303
26 S 115 BAC^M 1503 463
31 B 116 BML^G 466 924
36 S 117 BBW 560 766
24 S 118 ABB 778 485
32 S 119 BCS 356 571
28 B 120 AIU 1306 858
11 S 121 AWP 566 344
16 S 122 AWF 838 850
6 B 123 ACN 1495 500
0 S 124 AIO 1736 88
4 B 125 AGRO 890 338
26 S 126 AQNB 1579 89
22 B 127 BAC^S 1365 136
25 S 128 ALIT 1252 81
35 S 129 BMI 437 583
23 S 130 ABR^D 876 296
0 B 131 ARMK 1289 559
30 B 132 BF/A 614 506
18 B 133 ATI 1052 419
8 S 134 APG 429 617
21 S 135 AX 1825 566
9 B 136 BC^B 1501 172
34 S 137 ARR 988 654
11 B 138 ABB 1287 320
25 B 139 ARI 1841 819
33 B 140 BEPI 892 462
31 B 141 AIO 190 489
5 B 142 ACM 362 915
29 B 143 AZZ 1383 484
30 S 144 BAX 891 118
1 B 145 BBDO 652 248
0 S 146 BMEZ 940 284
11 B 147 AVAL 428 888
13 B 148 BHG 950 392
3 S 149 ATR 1866 40
27 B 150 BGS 188 834
13 S 151 AVAL 790 255
31 B 152 BLX 331 415
34 B 153 AVD 1829 715
11 S 154 AIU 161 224
32 B 155 AVNS 723 905
32 B 156 BIP^B 678 668
39 S 157 ATO 1429 94
4 B 158 AROC 205 957
36 B 159 AWF 1800 170
34 B 160 AEVA 1637 21
15 S 161 AGO 226 122
21 B 162 AHH^A 1892 768
23 B 163 BIO/B 1621 504
33 B 164 ARW 667 767
13 S 165 ATGE 1164 532
18 S 166 BF/A 1908 924
38 S 167 AWK 118 189
31 S 168 ALLG 1552 39
25 B 169 ALEX 1847 724
7 S 170 ABBV 479 996
6 B 171 AR 1346 757
36 B 172 AWK 1253 87
5 S 173 BIPI 1850 672
6 B 174 BILL 375 452
4 B 175 AAM^A 122 813
33 S 176 BHG 260 426
26 B 177 ALL^H 618 862
6 S 178 BBY 323 576
32 S 179 ARDC 1978 457
33 B 180 ABM 1807 623
5 S 181 BKU 1329 365
11 B 182 BLK 1880 279
22 S 183 BIG 620 141
26 B 184 BKN 1576 175
28 S 185 BALY 1918 144
37 S 186 AWF 992 678
6 S 187 ACDI 1294 365
27 S 188 AON 711 597
7 S 189 BGY 547 642
14 B 190 BIPC 1390 619
1 S 191 APLE 1886 762
35 S 192 AL 1446 973
30 B 193 AMH 1906 973
15 S 194 AGL 1483 263
20 B 195 BIO 847 548
39 S 196 ALL^I 586 413
31 B 197 BAC^E 1813 26
12 S 198 ATTO 728 556
29 B 199 AMX 1028 973
7 S 200 AMAM 1938 266
10 B 201 AFB 221 341
19 B 202 AU 418 286
19 S 203 APCA 265 397
10 B 204 BAC^B 638 619
16 B 205 BACA 445 48
38 B 206 AVA 1017 209
13 S 207 AVNS 191 912
19 S 208 AXS 1197 115
25 S 209 BEKE 1318 279
24 B 210 AEL^A 979 594
8 B 211 AXL 267 713
11 B 212 BERY 1714 792
20 B 213 AQNU 1729 215
2 B 214 BBN 834 488
32 S 215 ADNT 1443 24
31 S 216 BGSF 1201 727
27 S 217 BGSF 1048 680
34 B 218 AGR 1403 679
9 S 219 AGR 714 859
38 B 220 AVD 565 266
9 B 221 AGO 238 346
12 B 222 AVNT 1259 660
5 B 223 ACP 169 858
33 B 224 BKDT 767 719
10 B 225 AC 1866 714
24 B 226 ATH^C 1748 272
10 S 227 ASG 1969 423
0 S 228 BAC 1335 553
11 S 229 AVAL 1698 51
38 S 230 AIV 1421 340
12 B 231 ACR 1152 443
0 S 232 AHL^D 1707 621
18 B 233 AMC 154 725
27 S 234 AGM^F 1799 738
25 B 235 AMRX 1420 943
10 S 236 ABR 151 735
35 B 237 BALL 1630 461
31 S 238 ALX 727 361
4 S 239 ARMK 1768 557
13 S 240 AHT^H 1820 908
34 S 241 AVA 930 354
30 S 242 AGTI 1336 192
28 B 243 BML^H 117 489
32 S 244 BDXB 1590 234
27 S 245 AFGB 1048 203
17 B 246 ACA 103 853
0 S 247 ANF 1151 87
33 S 248 BH 1870 503
17 B 249 AJG 544 889
22 S 250 AMOV 753 946
18 B 251 ACP^A 1423 391
5 S 252 AZZ 193 440
14 S 253 APRN 1566 862
18 S 254 BAM 841 383
35 B 255 AFT 875 412
24 B 256 AMP 1915 794
27 S 257 AGL 1261 641
6 S 258 ATEN 1651 170
16 S 259 BIP 460 172
11 S 260 ACR 495 638
4 B 261 ABR 1471 749
29 B 262 AGTI 1775 252
30 S 263 ARI 1411 978
33 B 264 BA 611 812
18 B 265 AEE 1673 875
7 B 266 ABR^F 1660 268
18 B 267 BIG 1960 561
11 B 268 BFAM 813 955
39 S 269 AHT^F 1918 674
9 B 270 AC 693 833
13 B 271 BGSX 1911 552
12 B 272 ALTG^A 944 306
31 B 273 BGSF 1691 103
12 S 274 BCAT 1787 53
17 B 275 AGD 1915 326
12 B 276 ADC 1790 738
24 S 277 BLE 1701 531
36 B 278 AHH^A 912 691
10 S 279 AXS^E 1289 588
34 S 280 AGS 1656 925
23 B 281 ALIT 1595 86
11 S 282 BHLB 138 316
0 B 283 AZUL 570 639
33 B 284 AKA 203 946
19 B 285 ACCO 409 600
25 B 286 AVK 1925 599
10 B 287 ALL^B 1801 658
1 S 288 BME 1230 223
2 B 289 BBAR 1842 824
15 S 290 ARGO 108 125
17 S 291 AC 273 632
25 S 292 AHL^E 540 605
27 B 293 APTV 1586 553
22 S 294 BBAR 279 849
38 B 295 AMPY 1529 777
38 B 296 ASG 1228 512
37 S 297 ABEV 1205 642
16 S 298 ARMK 1474 736
14 S 299 AFL 1383 465
2 B 300 ACCO 869 147
21 S 301 ATI 416 737
8 B 302 ATKR 1635 896
39 S 303 BKD 1505 863
5 S 304 AEL^A 459 670
28 B 305 AAC 1069 297
1 S 306 BCS 1308 19
12 B 307 BAC^E 1551 213
25 S 308 AIU 1706 861
19 S 309 AGAC 1240 320
11 S 310 BEPC 1646 205
18 B 311 BDXB 1720 200
5 S 312 BHK 1978 793
23 S 313 AGCO 1416 350
22 S 314 BDXB 179 473
29 B 315 AVNT 1376 735
32 B 316 AXAC 1653 726
20 B 317 BGY 658 458
31 S 318 ANVS 137 343
1 S 319 ATEN 1037 93
25 S 320 AHH 1410 888
20 B 321 BIGZ 124 582
27 S 322 ACDI 917 915
0 B 323 BDJ 1216 133
9 S 324 ALIT 1995 364
24 B 325 ATO 1277 153
31 B 326 ACI 428 788
19 B 327 BFS^E 226 426
13 S 328 ALK 762 101
39 B 329 BFH 1269 358
29 B 330 BEKE 435 182
28 B 331 ASPN 1648 782
23 S 332 BHVN 1288 766
11 B 333 BKH 540 272
2 B 334 BAK 1219 266
13 B 335 ARR^C 277 672
15 B 336 AIV 1101 696
15 S 337 ABR^F 744 301
29 S 338 BML^J 1323 203
38 S 339 AHT^D 254 900
26 B 340 AIU 1574 568
7 S 341 APRN 1472 701
22 S 342 ARGO^A 990 499
17 S 343 AIC 1325 525
5 B 344 AGCO 756 496
4 S 345 BLND 254 202
5 B 346 ANF 1229 379
3 S 347 ACP 1015 405
10 S 348 ABC 1070 697
16 S 349 AHT^H 1048 886
35 B 350 AFT 628 156
11 B 351 AHT^D 1313 719
18 S 352 BAC^L 527 135
7 S 353 BFS 1046 697
28 B 354 BAC^L 1931 680
18 B 355 BBY 1354 805
29 B 356 ACP^A 1565 359
33 B 357 APE 669 118
37 S 358 BEKE 1460 716
10 S 359 BABA 974 769
6 B 360 BIP 907 234
28 B 361 BKSY 1602 740
31 B 362 BHR^D 1070 189
8 S 363 BC^A 1757 311
36 S 364 BDN 1687 10
30 B 365 BFZ 445 912
34 S 366 ARNC 133 282
31 S 367 BBD 1052 85
2 B 368 AAIN 975 151
28 B 369 AGRO 1441 762
39 S 370 ATR 1997 364
34 B 371 BKU 1710 406
10 B 372 BCAT 704 508
38 B 373 AFGC 1270 114
10 B 374 AWK 747 212
19 B 375 BDN 1020 253
36 S 376 AHT^D 1548 487
23 B 377 AGTI 718 489
24 B 378 AVY 899 603
11 B 379 BCO 449 996
6 S 380 APO 548 724
1 B 381 ANAC 742 252
26 B 382 AON 1918 397
26 S 383 BGX 918 947
3 B 384 BEST 1093 87
3 S 385 BFS^E 884 837
16 S 386 BB 297 100
36 S 387 BBVA 1758 176
36 B 388 BBY 1439 964
38 B 389 BHG 753 667
26 B 390 BH 1292 996
14 B 391 ATEK 1187 187
15 S 392 BGR 345 83
26 B 393 ALIT 1941 390
12 S 394 BBW 986 434
29 B 395 AEM 423 404
25 B 396 AME 861 140
22 S 397 BC 1646 223
13 S 398 AGCO 1274 148
20 S 399 BAP 1643 367
31 B 400 ASGN 1810 301
18 B 401 AMN 1808 967
2 B 402 BGS 1955 580
25 B 403 ALG 1603 481
18 S 404 AVNT 1531 39
31 B 405 AHT^F 1916 113
28 S 406 BHR^D 1117 739
36 S 407 AG 321 352
11 B 408 BLE 749 824
27 S 409 AFB 1330 790
31 B 410 AM 1821 222
35 S 411 BBN 1730 879
34 B 412 ATUS 598 598
22 S 413 BAC^P 1234 775
5 B 414 ANVS 1722 465
39 S 415 BCSF 266 966
28 B 416 AGD 1186 901
22 B 417 BIO/B 329 454
32 S 418 ATCO^H 1908 627
33 B 419 AEE 1328 998
27 B 420 ARGO 1708 856
12 B 421 AMX 1982 317
32 S 422 AGM^F 503 279
37 B 423 ATCO^D 1900 818
3 S 424 BGSF 1000 669
19 B 425 BHR^D 349 173
0 B 426 AAN 1979 936
14 B 427 BIG 152 853
39 S 428 AIC 1599 278
33 B 429 AHT^I 1005 226
33 B 430 ARDC 1969 166
18 B 431 ATR 1188 774
8 B 432 AIC 1428 883
22 B 433 AXAC 734 416
16 S 434 AMAM 1470 269
34 S 435 AZO 776 255
3 S 436 AOMR 223 583
7 S 437 AMBC 872 659
6 B 438 BAC 1760 830
19 B 439 ANAC 1703 257
8 B 440 BIG 991 121
21 S 441 AFGD 694 93
11 S 442 BHE 1454 407
20 B 443 BKT 1029 228
3 B 444 AMBP 706 429
8 B 445 AQNA 707 355
1 B 446 APCA 1288 153
1 S 447 B 1084 737
29 S 448 BIG 1954 972
30 S 449 BFS 1031 895
20 B 450 AMTD 1150 791
18 B 451 AQNA 1792 392
3 S 452 AFGD 377 388
14 B 453 BDN 470 909
35 S 454 BEPH 1804 219
11 B 455 AHT^F 1019 11
23 B 456 BBWI 1335 122
1 B 457 AKO/B 1088 226
27 B 458 AMRC 1212 947
1 S 459 AMRX 1191 695
12 S 460 AA 1185 548
33 B 461 AER 784 309
19 B 462 AKO/A 607 914
34 S 463 AWR 1856 636
17 S 464 AON 1915 947
